<?xml version="1.0" encoding="utf-8"?>
<!-- This URDF was automatically created by SolidWorks to URDF Exporter! Originally created by Stephen Brawner (brawner@gmail.com) 
     Commit Version: 1.5.1-0-g916b5db  Build Version: 1.5.7152.31018
     For more information, please see http://wiki.ros.org/sw_urdf_exporter -->
<robot
  name="swerve_drive">
  <link
    name="base_link">
    <inertial>
      <origin
        xyz="-0.073441 0.0048344 0.14539"
        rpy="0 0 0" />
      <mass
        value="9.9142" />
      <inertia
        ixx="0.21521"
        ixy="-0.001446"
        ixz="-0.00010869"
        iyy="0.11841"
        iyz="5.4379E-05"
        izz="0.31271" />
    </inertial>
    <visual>
      <origin
        xyz="0 0 0"
        rpy="0 0 0" />
      <geometry>
        <mesh
          filename="package://swerve_drive_description/meshes/base_link.STL" />
      </geometry>
      <material
        name="">
        <color
          rgba="0.75294 0.75294 0.75294 1" />
      </material>
    </visual>
    <collision>
      <origin
        xyz="0 0 0"
        rpy="0 0 0" />
      <geometry>
        <mesh
          filename="package://swerve_drive_description/meshes/base_link.STL" />
      </geometry>
    </collision>
  </link>
  <link
    name="lf_swerve_link">
    <inertial>
      <origin
        xyz="-6.5343E-06 0.003953 -0.024575"
        rpy="0 0 0" />
      <mass
        value="0.23291" />
      <inertia
        ixx="0.00017789"
        ixy="3.1284E-09"
        ixz="9.3072E-09"
        iyy="0.00031161"
        iyz="2.3005E-08"
        izz="0.00028635" />
    </inertial>
    <visual>
      <origin
        xyz="0 0 0"
        rpy="0 0 0" />
      <geometry>
        <mesh
          filename="package://swerve_drive_description/meshes/swerve_link.STL" />
      </geometry>
      <material
        name="">
        <color
          rgba="0.75294 0.75294 0.75294 1" />
      </material>
    </visual>
    <collision>
      <origin
        xyz="0 0 0"
        rpy="0 0 0" />
      <geometry>
        <mesh
          filename="package://swerve_drive_description/meshes/swerve_link.STL" />
      </geometry>
    </collision>
  </link>
  <joint
    name="lf_swerve_joint"
    type="continuous">
    <origin
      xyz="0.24858 0.17929 0.096509"
      rpy="0 0 0" />
    <parent
      link="base_link" />
    <child
      link="lf_swerve_link" />
    <axis
      xyz="0 0 1" />
  </joint>
  <link
    name="lf_wheel_link">
    <inertial>
      <origin
        xyz="-1.1437E-05 -4.8244E-06 -7.4559E-06"
        rpy="0 0 0" />
      <mass
        value="0.39722" />
      <inertia
        ixx="0.00072419"
        ixy="-2.8256E-08"
        ixz="2.0907E-08"
        iyy="0.0013599"
        iyz="-1.7286E-08"
        izz="0.00072418" />
    </inertial>
    <visual>
      <origin
        xyz="0 0 0"
        rpy="0 0 0" />
      <geometry>
        <mesh
          filename="package://swerve_drive_description/meshes/wheel_link.STL" />
      </geometry>
      <material
        name="">
        <color
          rgba="0.75294 0.75294 0.75294 1" />
      </material>
    </visual>
    <collision>
      <origin
        xyz="0 0 0"
        rpy="0 0 0" />
      <geometry>
        <mesh
          filename="package://swerve_drive_description/meshes/wheel_link.STL" />
      </geometry>
    </collision>
  </link>
  <joint
    name="lf_wheel_joint"
    type="continuous">
    <origin
      xyz="0 0.00047482 -0.07"
      rpy="0 0 0" />
    <parent
      link="lf_swerve_link" />
    <child
      link="lf_wheel_link" />
    <axis
      xyz="0 -1 0" />
  </joint>
  <link
    name="rf_swerve_link">
    <inertial>
      <origin
        xyz="-6.5343E-06 0.003953 -0.024575"
        rpy="0 0 0" />
      <mass
        value="0.23291" />
      <inertia
        ixx="0.00017789"
        ixy="3.1284E-09"
        ixz="9.3072E-09"
        iyy="0.00031161"
        iyz="2.3005E-08"
        izz="0.00028635" />
    </inertial>
    <visual>
      <origin
        xyz="0 0 0"
        rpy="0 0 0" />
      <geometry>
        <mesh
          filename="package://swerve_drive_description/meshes/swerve_link.STL" />
      </geometry>
      <material
        name="">
        <color
          rgba="0.75294 0.75294 0.75294 1" />
      </material>
    </visual>
    <collision>
      <origin
        xyz="0 0 0"
        rpy="0 0 0" />
      <geometry>
        <mesh
          filename="package://swerve_drive_description/meshes/swerve_link.STL" />
      </geometry>
    </collision>
  </link>
  <joint
    name="rf_swerve_joint"
    type="continuous">
    <origin
      xyz="0.24858 -0.18071 0.096509"
      rpy="0 0 0" />
    <parent
      link="base_link" />
    <child
      link="rf_swerve_link" />
    <axis
      xyz="0 0 1" />
  </joint>
  <link
    name="rf_wheel_link">
    <inertial>
      <origin
        xyz="-1.1437E-05 -4.8244E-06 -7.4559E-06"
        rpy="0 0 0" />
      <mass
        value="0.39722" />
      <inertia
        ixx="0.00072419"
        ixy="-2.8256E-08"
        ixz="2.0907E-08"
        iyy="0.0013599"
        iyz="-1.7286E-08"
        izz="0.00072418" />
    </inertial>
    <visual>
      <origin
        xyz="0 0 0"
        rpy="0 0 0" />
      <geometry>
        <mesh
          filename="package://swerve_drive_description/meshes/wheel_link.STL" />
      </geometry>
      <material
        name="">
        <color
          rgba="0.75294 0.75294 0.75294 1" />
      </material>
    </visual>
    <collision>
      <origin
        xyz="0 0 0"
        rpy="0 0 0" />
      <geometry>
        <mesh
          filename="package://swerve_drive_description/meshes/wheel_link.STL" />
      </geometry>
    </collision>
  </link>
  <joint
    name="rf_wheel_joint"
    type="continuous">
    <origin
      xyz="0 0.00047482 -0.07"
      rpy="0 0 0" />
    <parent
      link="rf_swerve_link" />
    <child
      link="rf_wheel_link" />
    <axis
      xyz="0 -1 0" />
  </joint>
  <link
    name="rr_swerve_link">
    <inertial>
      <origin
        xyz="-6.5343E-06 0.003953 -0.024575"
        rpy="0 0 0" />
      <mass
        value="0.23291" />
      <inertia
        ixx="0.00017789"
        ixy="3.1284E-09"
        ixz="9.3072E-09"
        iyy="0.00031161"
        iyz="2.3005E-08"
        izz="0.00028635" />
    </inertial>
    <visual>
      <origin
        xyz="0 0 0"
        rpy="0 0 0" />
      <geometry>
        <mesh
          filename="package://swerve_drive_description/meshes/swerve_link.STL" />
      </geometry>
      <material
        name="">
        <color
          rgba="0.75294 0.75294 0.75294 1" />
      </material>
    </visual>
    <collision>
      <origin
        xyz="0 0 0"
        rpy="0 0 0" />
      <geometry>
        <mesh
          filename="package://swerve_drive_description/meshes/swerve_link.STL" />
      </geometry>
    </collision>
  </link>
  <joint
    name="rr_swerve_joint"
    type="continuous">
    <origin
      xyz="-0.28642 -0.18071 0.096509"
      rpy="0 0 0" />
    <parent
      link="base_link" />
    <child
      link="rr_swerve_link" />
    <axis
      xyz="0 0 1" />
  </joint>
  <link
    name="rr_wheel_link">
    <inertial>
      <origin
        xyz="-1.1437E-05 -4.8244E-06 -7.4559E-06"
        rpy="0 0 0" />
      <mass
        value="0.39722" />
      <inertia
        ixx="0.00072419"
        ixy="-2.8256E-08"
        ixz="2.0907E-08"
        iyy="0.0013599"
        iyz="-1.7286E-08"
        izz="0.00072418" />
    </inertial>
    <visual>
      <origin
        xyz="0 0 0"
        rpy="0 0 0" />
      <geometry>
        <mesh
          filename="package://swerve_drive_description/meshes/wheel_link.STL" />
      </geometry>
      <material
        name="">
        <color
          rgba="0.75294 0.75294 0.75294 1" />
      </material>
    </visual>
    <collision>
      <origin
        xyz="0 0 0"
        rpy="0 0 0" />
      <geometry>
        <mesh
          filename="package://swerve_drive_description/meshes/wheel_link.STL" />
      </geometry>
    </collision>
  </link>
  <joint
    name="rr_wheel_joint"
    type="continuous">
    <origin
      xyz="0 0.00047482 -0.07"
      rpy="0 0 0" />
    <parent
      link="rr_swerve_link" />
    <child
      link="rr_wheel_link" />
    <axis
      xyz="0 -1 0" />
  </joint>
  <link
    name="lr_swerve_link">
    <inertial>
      <origin
        xyz="-6.5343E-06 0.003953 -0.024575"
        rpy="0 0 0" />
      <mass
        value="0.23291" />
      <inertia
        ixx="0.00017789"
        ixy="3.1284E-09"
        ixz="9.3072E-09"
        iyy="0.00031161"
        iyz="2.3005E-08"
        izz="0.00028635" />
    </inertial>
    <visual>
      <origin
        xyz="0 0 0"
        rpy="0 0 0" />
      <geometry>
        <mesh
          filename="package://swerve_drive_description/meshes/swerve_link.STL" />
      </geometry>
      <material
        name="">
        <color
          rgba="0.75294 0.75294 0.75294 1" />
      </material>
    </visual>
    <collision>
      <origin
        xyz="0 0 0"
        rpy="0 0 0" />
      <geometry>
        <mesh
          filename="package://swerve_drive_description/meshes/swerve_link.STL" />
      </geometry>
    </collision>
  </link>
  <joint
    name="lr_swerve_joint"
    type="continuous">
    <origin
      xyz="-0.28642 0.17929 0.096509"
      rpy="0 0 0" />
    <parent
      link="base_link" />
    <child
      link="lr_swerve_link" />
    <axis
      xyz="0 0 1" />
  </joint>
  <link
    name="lr_wheel_link">
    <inertial>
      <origin
        xyz="-1.1437E-05 -4.8244E-06 -7.4559E-06"
        rpy="0 0 0" />
      <mass
        value="0.39722" />
      <inertia
        ixx="0.00072419"
        ixy="-2.8256E-08"
        ixz="2.0907E-08"
        iyy="0.0013599"
        iyz="-1.7286E-08"
        izz="0.00072418" />
    </inertial>
    <visual>
      <origin
        xyz="0 0 0"
        rpy="0 0 0" />
      <geometry>
        <mesh
          filename="package://swerve_drive_description/meshes/wheel_link.STL" />
      </geometry>
      <material
        name="">
        <color
          rgba="0.75294 0.75294 0.75294 1" />
      </material>
    </visual>
    <collision>
      <origin
        xyz="0 0 0"
        rpy="0 0 0" />
      <geometry>
        <mesh
          filename="package://swerve_drive_description/meshes/wheel_link.STL" />
      </geometry>
    </collision>
  </link>
  <joint
    name="lr_wheel_joint"
    type="continuous">
    <origin
      xyz="0 0.00047482 -0.07"
      rpy="0 0 0" />
    <parent
      link="lr_swerve_link" />
    <child
      link="lr_wheel_link" />
    <axis
      xyz="0 -1 0" />
  </joint>
</robot>