<?xml version="1.0"?>
<robot xmlns:xacro="http://www.ros.org/wiki/xacro">
  <xacro:include filename="$(find swerve_drive_description)/urdf/wheel.gazebo.xacro" />
  <xacro:macro name="swerve_wheel" params="prefix side parent geometry_config swerve_joint wheel_joint links">

    <xacro:property name="sjo" value="${swerve_joint['origin']}" />
    <xacro:property name="sja" value="${swerve_joint['axis']}" />
    <xacro:property name="wjo" value="${wheel_joint['origin']}" />
    <xacro:property name="wja" value="${wheel_joint['axis']}" />
    <xacro:property name="sio" value="${links['swerve']['inertial']['origin']}" />
    <xacro:property name="sii" value="${links['swerve']['inertial']['inertia']}" />
    <xacro:property name="wio" value="${links['wheel']['inertial']['origin']}" />
    <xacro:property name="wii" value="${links['wheel']['inertial']['inertia']}" />
    <xacro:property name="svo" value="${geometry_config['swerve']['visual']['origin']}" />
    <xacro:property name="sco" value="${geometry_config['swerve']['collision']['origin']}" />
    <xacro:property name="wvo" value="${geometry_config['wheel']['visual']['origin']}" />
    <xacro:property name="wco" value="${geometry_config['wheel']['collision']['origin']}" />

    
    <link
        name="${prefix}${side}swerve_link">
        <inertial>
            <origin
                xyz="${sio['x']} ${sio['y']} ${sio['z']}"
                rpy="${sio['roll']} ${sio['pitch']} ${sio['yaw']}" />
            <mass
                value="${links['swerve']['inertial']['mass']}" />
            <inertia
                ixx="${sii['xx']}"
                ixy="0"
                ixz="0"
                iyy="${sii['yy']}"
                iyz="0"
                izz="${sii['zz']}" />
        </inertial>
        <visual>
            <origin
                xyz="${svo['x']} ${svo['y']} ${svo['z']}"
                rpy="${svo['roll']} ${svo['pitch']} ${svo['yaw']}" />
            <geometry>
                <mesh
                    filename="file://$(find ${geometry_config['package']})/${geometry_config['swerve']['visual']['path']}" />
            </geometry>
            <material
                name="">
                <color
                rgba="0.75294 0.75294 0.75294 1" />
            </material>
        </visual>
        <collision>
            <origin
                xyz="${sco['x']} ${sco['y']} ${sco['z']}"
                rpy="${sco['roll']} ${sco['pitch']} ${sco['yaw']}" />
            <geometry>
                <mesh
                    filename="file://$(find ${geometry_config['package']})/${geometry_config['swerve']['collision']['path']}" />
            </geometry>
        </collision>
    </link>
    <joint
        name="${prefix}${side}swerve_joint"
        type="continuous">
        <origin
            xyz="${sjo['x']} ${sjo['y']} ${sjo['z']}"
            rpy="${sjo['roll']} ${sjo['pitch']} ${sjo['yaw']}" />
        <parent
            link="${parent}" />
        <child
            link="${prefix}${side}swerve_link" />
        <axis
            xyz="${sja['x']} ${sja['y']} ${sja['z']}" />
        <limit
            effort="100"
            velocity="3.2" />
        <dynamics
            damping="100"
            friction="10" />
    </joint>
    <link
        name="${prefix}${side}wheel_link">
        <inertial>
            <origin
                xyz="${wio['x']} ${wio['y']} ${wio['z']}"
                rpy="${wio['roll']} ${wio['pitch']} ${wio['yaw']}" />
            <mass
                value="${links['swerve']['inertial']['mass']}" />
            <inertia
                ixx="${wii['xx']}"
                ixy="0"
                ixz="0"
                iyy="${wii['yy']}"
                iyz="0"
                izz="${wii['zz']}" />
        </inertial>
        <visual>
            <origin
                xyz="${wco['x']} ${wco['y']} ${wco['z']}"
                rpy="${wco['roll']} ${wco['pitch']} ${wco['yaw']}" />
            <geometry>
                <mesh
                    filename="file://$(find ${geometry_config['package']})/${geometry_config['wheel']['visual']['path']}" />
            </geometry>
            <material
                name="">
                <color
                rgba="0.75294 0.75294 0.75294 1" />
            </material>
        </visual>
        <collision>
            <origin
                xyz="${wvo['x']} ${wvo['y']} ${wvo['z']}"
                rpy="${wvo['roll']} ${wvo['pitch']} ${wvo['yaw']}" />
            <geometry>
                <mesh
                    filename="file://$(find ${geometry_config['package']})/${geometry_config['wheel']['collision']['path']}" />
            </geometry>
        </collision>
    </link>
    <joint
        name="${prefix}${side}wheel_joint"
        type="continuous">
        <origin
            xyz="${wjo['x']} ${wjo['y']} ${wjo['z']}"
            rpy="${wjo['roll']} ${wjo['pitch']} ${wjo['yaw']}" />
        <parent
            link="${prefix}${side}swerve_link" />
        <child
            link="${prefix}${side}wheel_link" />
        <axis
            xyz="${wja['x']} ${wja['y']} ${wja['z']}" />
        <limit
            effort="30"
            velocity="12.7" />
        <dynamics 
            damping="0.4"
            friction="0.04" />
    </joint>
    <xacro:wheel_gazebo side="${side}" prefix="${prefix}"/>
  </xacro:macro>
</robot>